<?xml version='1.0'?>
<sdf version='1.5'>
  <model name='SHC09'>
    <pose>0 0 0.5 0 0 0</pose>
    <link name='base_link'>
      <inertial>
        <pose>0 0 0.117687 0 0 0</pose>
        <mass>1.6</mass>
        <inertia>
            <ixx>0.01149</ixx>
            <ixy>0</ixy>
            <ixz>0</ixz>
            <iyy>0.01153</iyy>
            <iyz>0</iyz>
            <izz>0.004865</izz>
          </inertia>
      </inertial>
      <visual name='visual'>
        <pose>0 0 0 0 -0 3.1415926</pose>
        <geometry>
          <mesh>
            <uri>model://SHC09/meshes/Battery-6s-10000-2170.STL</uri>
            <scale>1 1 1</scale>
          </mesh>
        </geometry>
        <material>
          <lighting>1</lighting>
          <script>
            <uri>file://media/materials/scripts/gazebo.material</uri>
            <name>Gazebo/Blue</name>
          </script>
          <shader type='pixel'/>
          <emissive>0 0 0 1</emissive>
        </material>
        <transparency>0</transparency>
        <cast_shadows>1</cast_shadows>
      </visual>
      <collision name='collision'>
        <pose>0.0 -0.0 0.07 0 -0 0</pose>
        <geometry>
          <box>
            <size>0.25 0.25 0.6</size>
          </box>
        </geometry>
      </collision>
      <gravity>1</gravity>
      <velocity_decay/>
      <self_collide>0</self_collide>
    </link>
    <link name='link_1'>
      <inertial>
        <mass>0.00000001</mass>
        <inertia>
          <ixx>0.000001</ixx>
          <ixy>0.0</ixy>
          <iyy>0.000001</iyy>
          <ixz>0.0</ixz>
          <iyz>0.0</iyz>
          <izz>0.000001</izz>
        </inertia>
      </inertial>

      <visual name='visual'>
        <pose>0 0 0 0 -0 3.1415926</pose>
        <geometry>
          <mesh>
            <uri>model://SHC09/meshes/bec-Hobbywing-Platinum 60A.STL</uri>
            <scale>1 1 1</scale>
          </mesh>
        </geometry>
        <material>
          <lighting>1</lighting>
          <script>
            <uri>file://media/materials/scripts/gazebo.material</uri>
            <name>Gazebo/Black</name>
          </script>
          <shader type='pixel'/>
          <emissive>0 0 0 1</emissive>
        </material>
        <transparency>0</transparency>
        <cast_shadows>1</cast_shadows>
      </visual>
    </link>
    <link name='link_10'>
      <!-- <inertial>
        <mass>0.106</mass>
        <inertia>
          <ixx>0.000411</ixx>
          <ixy>0</ixy>
          <ixz>0</ixz>
          <iyy>0.000411</iyy>
          <iyz>0</iyz>
          <izz>0.000757</izz>
        </inertia>
        <pose>0 0 -0.131291 0 -0 0</pose>
      </inertial> -->
      <inertial>
        <mass>0.00000001</mass>
        <inertia>
          <ixx>0.000001</ixx>
          <ixy>0.0</ixy>
          <iyy>0.000001</iyy>
          <ixz>0.0</ixz>
          <iyz>0.0</iyz>
          <izz>0.000001</izz>
        </inertia>
      </inertial>
      <visual name='visual'>
        <pose>0 0 0 0 -0 3.1415926</pose>
        <geometry>
          <mesh>
            <uri>model://SHC09/meshes/duct-b-SHW09.STL</uri>
            <scale>1 1 1</scale>
          </mesh>
        </geometry>
        <material>
          <lighting>1</lighting>
          <script>
            <uri>file://media/materials/scripts/gazebo.material</uri>
            <name>Gazebo/Black</name>
          </script>
          <shader type='pixel'/>
          <emissive>0 0 0 1</emissive>
        </material>
        <transparency>0</transparency>
        <cast_shadows>1</cast_shadows>
      </visual>
    </link>
    <link name='link_11'>
      <inertial>
        <mass>0.00000001</mass>
        <inertia>
          <ixx>0.000001</ixx>
          <ixy>0.0</ixy>
          <iyy>0.000001</iyy>
          <ixz>0.0</ixz>
          <iyz>0.0</iyz>
          <izz>0.000001</izz>
        </inertia>
      </inertial>

      <visual name='visual'>
        <pose>0 0 0 0 -0 3.1415926</pose>
        <geometry>
          <mesh>
            <uri>model://SHC09/meshes/duct-SH09-1.STL</uri>
            <scale>1 1 1</scale>
          </mesh>
        </geometry>
        <material>
          <lighting>1</lighting>
          <script>
            <uri>file://media/materials/scripts/gazebo.material</uri>
            <name>Gazebo/White</name>
          </script>
          <shader type='pixel'/>
          <emissive>0 0 0 1</emissive>
        </material>
        <transparency>0</transparency>
        <cast_shadows>1</cast_shadows>
      </visual>
    </link>
    <link name='link_12'>
      <inertial>
        <mass>0.00000001</mass>
        <inertia>
          <ixx>0.000001</ixx>
          <ixy>0.0</ixy>
          <iyy>0.000001</iyy>
          <ixz>0.0</ixz>
          <iyz>0.0</iyz>
          <izz>0.000001</izz>
        </inertia>
      </inertial>

      <visual name='visual'>
        <pose>0 0 0 0 -0 3.1415926</pose>
        <geometry>
          <mesh>
            <uri>model://SHC09/meshes/duct-SH09-2.STL</uri>
            <scale>1 1 1</scale>
          </mesh>
        </geometry>
        <material>
          <lighting>1</lighting>
          <script>
            <uri>file://media/materials/scripts/gazebo.material</uri>
            <name>Gazebo/White</name>
          </script>
          <shader type='pixel'/>
          <emissive>0 0 0 1</emissive>
        </material>
        <transparency>0</transparency>
        <cast_shadows>1</cast_shadows>
      </visual>
    </link>
    <link name='link_13'>
      <inertial>
        <mass>0.00000001</mass>
        <inertia>
          <ixx>0.000001</ixx>
          <ixy>0.0</ixy>
          <iyy>0.000001</iyy>
          <ixz>0.0</ixz>
          <iyz>0.0</iyz>
          <izz>0.000001</izz>
        </inertia>
      </inertial>

      <visual name='visual'>
        <pose>0 0 0 0 -0 3.1415926</pose>
        <geometry>
          <mesh>
            <uri>model://SHC09/meshes/duct-SH09-3.STL</uri>
            <scale>1 1 1</scale>
          </mesh>
        </geometry>
        <material>
          <lighting>1</lighting>
          <script>
            <uri>file://media/materials/scripts/gazebo.material</uri>
            <name>Gazebo/White</name>
          </script>
          <shader type='pixel'/>
          <emissive>0 0 0 1</emissive>
        </material>
        <transparency>0</transparency>
        <cast_shadows>1</cast_shadows>
      </visual>
    </link>
    <link name='link_14'>
      <inertial>
        <mass>0.00000001</mass>
        <inertia>
          <ixx>0.000001</ixx>
          <ixy>0.0</ixy>
          <iyy>0.000001</iyy>
          <ixz>0.0</ixz>
          <iyz>0.0</iyz>
          <izz>0.000001</izz>
        </inertia>
      </inertial>

      <visual name='visual'>
        <pose>0 0 0 0 -0 3.1415926</pose>
        <geometry>
          <mesh>
            <uri>model://SHC09/meshes/fuselage-09.STL</uri>
            <scale>1 1 1</scale>
          </mesh>
        </geometry>
        <material>
          <lighting>1</lighting>
          <script>
            <uri>file://media/materials/scripts/gazebo.material</uri>
            <name>Gazebo/Black</name>
          </script>
          <shader type='pixel'/>
          <emissive>0 0 0 1</emissive>
        </material>
        <transparency>0</transparency>
        <cast_shadows>1</cast_shadows>
      </visual>
    </link>
    <link name='link_15'>
      <inertial>
        <mass>0.00000001</mass>
        <inertia>
          <ixx>0.000001</ixx>
          <ixy>0.0</ixy>
          <iyy>0.000001</iyy>
          <ixz>0.0</ixz>
          <iyz>0.0</iyz>
          <izz>0.000001</izz>
        </inertia>
      </inertial>

      <visual name='visual'>
        <pose>0 0 0 0 -0 3.1415926</pose>
        <geometry>
          <mesh>
            <uri>model://SHC09/meshes/head-SHC09-1.STL</uri>
            <scale>1 1 1</scale>
          </mesh>
        </geometry>
        <material>
          <lighting>1</lighting>
          <script>
            <uri>file://media/materials/scripts/gazebo.material</uri>
            <name>Gazebo/Black</name>
          </script>
          <shader type='pixel'/>
          <emissive>0 0 0 1</emissive>
        </material>
        <transparency>0</transparency>
        <cast_shadows>1</cast_shadows>
      </visual>
    </link>
    <link name='link_16'>
      <inertial>
        <mass>0.00000001</mass>
        <inertia>
          <ixx>0.000001</ixx>
          <ixy>0.0</ixy>
          <iyy>0.000001</iyy>
          <ixz>0.0</ixz>
          <iyz>0.0</iyz>
          <izz>0.000001</izz>
        </inertia>
      </inertial>

      <visual name='visual'>
        <pose>0 0 0 0 -0 3.1415926</pose>
        <geometry>
          <mesh>
            <uri>model://SHC09/meshes/head-SHC09-2.STL</uri>
            <scale>1 1 1</scale>
          </mesh>
        </geometry>
        <material>
          <lighting>1</lighting>
          <script>
            <uri>file://media/materials/scripts/gazebo.material</uri>
            <name>Gazebo/Grey</name>
          </script>
          <shader type='pixel'/>
          <emissive>0 0 0 1</emissive>
        </material>
        <transparency>0</transparency>
        <cast_shadows>1</cast_shadows>
      </visual>
    </link>
    <link name='link_17'>
      <inertial>
        <mass>0.00000001</mass>
        <inertia>
          <ixx>0.000001</ixx>
          <ixy>0.0</ixy>
          <iyy>0.000001</iyy>
          <ixz>0.0</ixz>
          <iyz>0.0</iyz>
          <izz>0.000001</izz>
        </inertia>
      </inertial>

      <visual name='visual'>
        <pose>0 0 0 0 -0 3.1415926</pose>
        <geometry>
          <mesh>
            <uri>model://SHC09/meshes/motor-Sunnysky-X3520-7-780KV III.STL</uri>
            <scale>1 1 1</scale>
          </mesh>
        </geometry>
        <material>
          <lighting>1</lighting>
          <script>
            <uri>file://media/materials/scripts/gazebo.material</uri>
            <name>Gazebo/Red</name>
          </script>
          <shader type='pixel'/>
          <emissive>0 0 0 1</emissive>
        </material>
        <transparency>0</transparency>
        <cast_shadows>1</cast_shadows>
      </visual>
    </link>
    <link name='rotor'>
      <inertial>
        <mass>0.01836</mass>
        <inertia>
          <ixx>0.000019</ixx>
          <ixy>0</ixy>
          <ixz>0</ixz>
          <iyy>0.000019</iyy>
          <iyz>0</iyz>
          <izz>0.000037</izz>
        </inertia>
        <pose>-0.0 -0.0 -0.04250779552 0 -0 0</pose>
      </inertial>
      <gravity>1</gravity>
      <self_collide>0</self_collide>
      <kinematic>0</kinematic>
      <enable_wind>0</enable_wind>
      <visual name='visual'>
        <pose>0 0 0 0 -0 3.1415926</pose>
        <geometry>
          <mesh>
            <uri>model://SHC09/meshes/Rotor-iflight-13inch-2-CW-cut9.STL</uri>
            <scale>1 1 1</scale>
          </mesh>
        </geometry>
        <material>
          <lighting>1</lighting>
          <script>
            <uri>file://media/materials/scripts/gazebo.material</uri>
            <name>Gazebo/Black</name>
          </script>
          <shader type='pixel'/>
          <emissive>0 0 0 1</emissive>
        </material>
        <transparency>0</transparency>
        <cast_shadows>1</cast_shadows>
      </visual>
    </link>
    <link name='link_19'>
      <inertial>
        <mass>0.00000001</mass>
        <inertia>
          <ixx>0.000001</ixx>
          <ixy>0.0</ixy>
          <iyy>0.000001</iyy>
          <ixz>0.0</ixz>
          <iyz>0.0</iyz>
          <izz>0.000001</izz>
        </inertia>
      </inertial>

      <visual name='visual'>
        <pose>0 0 0 0 -0 3.1415926</pose>
        <geometry>
          <mesh>
            <uri>model://SHC09/meshes/RTK-antenna.STL</uri>
            <scale>1 1 1</scale>
          </mesh>
        </geometry>
        <material>
          <lighting>1</lighting>
          <script>
            <uri>file://media/materials/scripts/gazebo.material</uri>
            <name>Gazebo/Grey</name>
          </script>
          <shader type='pixel'/>
          <emissive>0 0 0 1</emissive>
        </material>
        <transparency>0</transparency>
        <cast_shadows>1</cast_shadows>
      </visual>
    </link>
    <link name='link_2'>
      <inertial>
        <mass>0.00000001</mass>
        <inertia>
          <ixx>0.000001</ixx>
          <ixy>0.0</ixy>
          <iyy>0.000001</iyy>
          <ixz>0.0</ixz>
          <iyz>0.0</iyz>
          <izz>0.000001</izz>
        </inertia>
      </inertial>

      <visual name='visual'>
        <pose>0 0 0 0 -0 3.1415926</pose>
        <geometry>
          <mesh>
            <uri>model://SHC09/meshes/box up-09.STL</uri>
            <scale>1 1 1</scale>
          </mesh>
        </geometry>
        <material>
          <lighting>1</lighting>
          <script>
            <uri>file://media/materials/scripts/gazebo.material</uri>
            <name>Gazebo/Grey</name>
          </script>
          <shader type='pixel'/>
          <emissive>0 0 0 1</emissive>
        </material>
        <transparency>0</transparency>
        <cast_shadows>1</cast_shadows>
      </visual>
    </link>
    <link name='link_20'>
      <inertial>
        <!-- <mass>0.01</mass>
        <inertia>
          <ixx>0.000000498</ixx>
          <ixy>0</ixy>
          <ixz>0</ixz>
          <iyy>0.00000081</iyy>
          <iyz>0</iyz>
          <izz>0.000000413</izz>
        </inertia> -->
        <mass>0.00000001</mass>
        <inertia>
          <ixx>0.000001</ixx>
          <ixy>0.0</ixy>
          <iyy>0.000001</iyy>
          <ixz>0.0</ixz>
          <iyz>0.0</iyz>
          <izz>0.000001</izz>
        </inertia>
        <pose>0.018145 0 -0.152522 0 -0 0</pose>
      </inertial>

      <visual name='visual'>
        <pose>0 0 0 0 -0 3.1415926</pose>
        <geometry>
          <mesh>
            <uri>model://SHC09/meshes/servo-KST-X08H-1.STL</uri>
            <scale>1 1 1</scale>
          </mesh>
        </geometry>
        <material>
          <lighting>1</lighting>
          <script>
            <uri>file://media/materials/scripts/gazebo.material</uri>
            <name>Gazebo/Red</name>
          </script>
          <shader type='pixel'/>
          <emissive>0 0 0 1</emissive>
        </material>
        <transparency>0</transparency>
        <cast_shadows>1</cast_shadows>
      </visual>
    </link>
    <link name='link_21'>
      <inertial>
        <!-- <mass>0.01</mass>
        <inertia>
          <ixx>0.000000732</ixx>
          <ixy>0</ixy>
          <ixz>0</ixz>
          <iyy>0.000000576</iyy>
          <iyz>0</iyz>
          <izz>0.000000413</izz>
        </inertia> -->
        <mass>0.00000001</mass>
        <inertia>
          <ixx>0.000001</ixx>
          <ixy>0.0</ixy>
          <iyy>0.000001</iyy>
          <ixz>0.0</ixz>
          <iyz>0.0</iyz>
          <izz>0.000001</izz>
        </inertia>
        <pose>0.009 -0.015714 -0.152522 0 -0 0</pose>
      </inertial>

      <visual name='visual'>
        <pose>0 0 0 0 -0 3.1415926</pose>
        <geometry>
          <mesh>
            <uri>model://SHC09/meshes/servo-KST-X08H-2.STL</uri>
            <scale>1 1 1</scale>
          </mesh>
        </geometry>
        <material>
          <lighting>1</lighting>
          <script>
            <uri>file://media/materials/scripts/gazebo.material</uri>
            <name>Gazebo/Red</name>
          </script>
          <shader type='pixel'/>
          <emissive>0 0 0 1</emissive>
        </material>
        <transparency>0</transparency>
        <cast_shadows>1</cast_shadows>
      </visual>
    </link>
    <link name='link_22'>
      <inertial>
        <!-- <mass>0.01</mass>
        <inertia>
          <ixx>0.000000732</ixx>
          <ixy>0</ixy>
          <ixz>0</ixz>
          <iyy>0.000000576</iyy>
          <iyz>0</iyz>
          <izz>0.000000413</izz>
        </inertia> -->
        <mass>0.00000001</mass>
        <inertia>
          <ixx>0.000001</ixx>
          <ixy>0.0</ixy>
          <iyy>0.000001</iyy>
          <ixz>0.0</ixz>
          <iyz>0.0</iyz>
          <izz>0.000001</izz>
        </inertia>
        <pose>-0.009072 -0.015714 -0.152522 0 -0 0</pose>
      </inertial>

      <visual name='visual'>
        <pose>0 0 0 0 -0 3.1415926</pose>
        <geometry>
          <mesh>
            <uri>model://SHC09/meshes/servo-KST-X08H-3.STL</uri>
            <scale>1 1 1</scale>
          </mesh>
        </geometry>
        <material>
          <lighting>1</lighting>
          <script>
            <uri>file://media/materials/scripts/gazebo.material</uri>
            <name>Gazebo/Red</name>
          </script>
          <shader type='pixel'/>
          <emissive>0 0 0 1</emissive>
        </material>
        <transparency>0</transparency>
        <cast_shadows>1</cast_shadows>
      </visual>
    </link>
    <link name='link_23'>
      <inertial>
        <!-- <mass>0.01</mass>
        <inertia>
          <ixx>0.0000004980968</ixx>
          <ixy>0</ixy>
          <ixz>0</ixz>
          <iyy>0.0000008106157</iyy>
          <iyz>0</iyz>
          <izz>0.0000004137767</izz>
        </inertia> -->
        <mass>0.00000001</mass>
        <inertia>
          <ixx>0.000001</ixx>
          <ixy>0.0</ixy>
          <iyy>0.000001</iyy>
          <ixz>0.0</ixz>
          <iyz>0.0</iyz>
          <izz>0.000001</izz>
        </inertia>
        <pose>-0.018145 0 -0.152522 0 -0 0</pose>
      </inertial>

      <visual name='visual'>
        <pose>0 0 0 0 -0 3.1415926</pose>
        <geometry>
          <mesh>
            <uri>model://SHC09/meshes/servo-KST-X08H-4.STL</uri>
            <scale>1 1 1</scale>
          </mesh>
        </geometry>
        <material>
          <lighting>1</lighting>
          <script>
            <uri>file://media/materials/scripts/gazebo.material</uri>
            <name>Gazebo/Red</name>
          </script>
          <shader type='pixel'/>
          <emissive>0 0 0 1</emissive>
        </material>
        <transparency>0</transparency>
        <cast_shadows>1</cast_shadows>
      </visual>
    </link>
    <link name='link_24'>
      <inertial>
        <!-- <mass>0.01</mass>
        <inertia>
          <ixx>0.0000007324859</ixx>
          <ixy>0</ixy>
          <ixz>0</ixz>
          <iyy>0.0000005762265</iyy>
          <iyz>0</iyz>
          <izz>0.0000004137767</izz>
        </inertia> -->
        <mass>0.00000001</mass>
        <inertia>
          <ixx>0.000001</ixx>
          <ixy>0.0</ixy>
          <iyy>0.000001</iyy>
          <ixz>0.0</ixz>
          <iyz>0.0</iyz>
          <izz>0.000001</izz>
        </inertia>
        <pose>-0.009072 0.015714 -0.152522 0 -0 0</pose>
      </inertial>

      <visual name='visual'>
        <pose>0 0 0 0 -0 3.1415926</pose>
        <geometry>
          <mesh>
            <uri>model://SHC09/meshes/servo-KST-X08H-5.STL</uri>
            <scale>1 1 1</scale>
          </mesh>
        </geometry>
        <material>
          <lighting>1</lighting>
          <script>
            <uri>file://media/materials/scripts/gazebo.material</uri>
            <name>Gazebo/Red</name>
          </script>
          <shader type='pixel'/>
          <emissive>0 0 0 1</emissive>
        </material>
        <transparency>0</transparency>
        <cast_shadows>1</cast_shadows>
      </visual>
    </link>
    <link name='link_25'>
      <inertial>
        <!-- <mass>0.01</mass>
        <inertia>
          <ixx>0.0000007324859</ixx>
          <ixy>0</ixy>
          <ixz>0</ixz>
          <iyy>0.0000005762265</iyy>
          <iyz>0</iyz>
          <izz>0.0000004137767</izz>
        </inertia> -->
        <mass>0.00000001</mass>
        <inertia>
          <ixx>0.000001</ixx>
          <ixy>0.0</ixy>
          <iyy>0.000001</iyy>
          <ixz>0.0</ixz>
          <iyz>0.0</iyz>
          <izz>0.000001</izz>
        </inertia>
        <pose>0.009072 0.015714 -0.152522 0 -0 0</pose>
      </inertial>

      <visual name='visual'>
        <pose>0 0 0 0 -0 3.1415926</pose>
        <geometry>
          <mesh>
            <uri>model://SHC09/meshes/servo-KST-X08H-6.STL</uri>
            <scale>1 1 1</scale>
          </mesh>
        </geometry>
        <material>
          <lighting>1</lighting>
          <script>
            <uri>file://media/materials/scripts/gazebo.material</uri>
            <name>Gazebo/Red</name>
          </script>
          <shader type='pixel'/>
          <emissive>0 0 0 1</emissive>
        </material>
        <transparency>0</transparency>
        <cast_shadows>1</cast_shadows>
      </visual>
    </link>
    <link name='link_26'>
      <inertial>
        <mass>0.00000001</mass>
        <inertia>
          <ixx>0.000001</ixx>
          <ixy>0.0</ixy>
          <iyy>0.000001</iyy>
          <ixz>0.0</ixz>
          <iyz>0.0</iyz>
          <izz>0.000001</izz>
        </inertia>
      </inertial>

      <visual name='visual'>
        <pose>0 0 0 0 -0 3.1415926</pose>
        <geometry>
          <mesh>
            <uri>model://SHC09/meshes/shelf1-SHC09.STL</uri>
            <scale>1 1 1</scale>
          </mesh>
        </geometry>
        <material>
          <lighting>1</lighting>
          <script>
            <uri>file://media/materials/scripts/gazebo.material</uri>
            <name>Gazebo/Grey</name>
          </script>
          <shader type='pixel'/>
          <emissive>0 0 0 1</emissive>
        </material>
        <transparency>0</transparency>
        <cast_shadows>1</cast_shadows>
      </visual>
    </link>
    <link name='link_27'>
      <inertial>
        <mass>0.00000001</mass>
        <inertia>
          <ixx>0.000001</ixx>
          <ixy>0.0</ixy>
          <iyy>0.000001</iyy>
          <ixz>0.0</ixz>
          <iyz>0.0</iyz>
          <izz>0.000001</izz>
        </inertia>
      </inertial>

      <visual name='visual'>
        <pose>0 0 0 0 -0 3.1415926</pose>
        <geometry>
          <mesh>
            <uri>model://SHC09/meshes/shelf2-SHC09.STL</uri>
            <scale>1 1 1</scale>
          </mesh>
        </geometry>
        <material>
          <lighting>1</lighting>
          <script>
            <uri>file://media/materials/scripts/gazebo.material</uri>
            <name>Gazebo/Grey</name>
          </script>
          <shader type='pixel'/>
          <emissive>0 0 0 1</emissive>
        </material>
        <transparency>0</transparency>
        <cast_shadows>1</cast_shadows>
      </visual>
    </link>
    <link name='link_28'>
      <inertial>
        <mass>0.00000001</mass>
        <inertia>
          <ixx>0.000001</ixx>
          <ixy>0.0</ixy>
          <iyy>0.000001</iyy>
          <ixz>0.0</ixz>
          <iyz>0.0</iyz>
          <izz>0.000001</izz>
        </inertia>
      </inertial>

      <visual name='visual'>
        <pose>0 0 0 0 -0 3.1415926</pose>
        <geometry>
          <mesh>
            <uri>model://SHC09/meshes/shelf3-09.STL</uri>
            <scale>1 1 1</scale>
          </mesh>
        </geometry>
        <material>
          <lighting>1</lighting>
          <script>
            <uri>file://media/materials/scripts/gazebo.material</uri>
            <name>Gazebo/Grey</name>
          </script>
          <shader type='pixel'/>
          <emissive>0 0 0 1</emissive>
        </material>
        <transparency>0</transparency>
        <cast_shadows>1</cast_shadows>
      </visual>
    </link>
    <link name='link_29'>
      <inertial>
        <mass>0.00000001</mass>
        <inertia>
          <ixx>0.000001</ixx>
          <ixy>0.0</ixy>
          <iyy>0.000001</iyy>
          <ixz>0.0</ixz>
          <iyz>0.0</iyz>
          <izz>0.000001</izz>
        </inertia>
      </inertial>

      <visual name='visual'>
        <pose>0 0 0 0 -0 3.1415926</pose>
        <geometry>
          <mesh>
            <uri>model://SHC09/meshes/shelf4-09.STL</uri>
            <scale>1 1 1</scale>
          </mesh>
        </geometry>
        <material>
          <lighting>1</lighting>
          <script>
            <uri>file://media/materials/scripts/gazebo.material</uri>
            <name>Gazebo/Grey</name>
          </script>
          <shader type='pixel'/>
          <emissive>0 0 0 1</emissive>
        </material>
        <transparency>0</transparency>
        <cast_shadows>1</cast_shadows>
      </visual>
    </link>
    <link name='CS4'>
      <inertial>
        <!-- <mass>0.006</mass>
        <inertia>
          <ixx>0.000001</ixx>
          <ixy>0</ixy>
          <ixz>0</ixz>
          <iyy>0.000004</iyy>
          <iyz>0</iyz>
          <izz>0.000003</izz>
        </inertia> -->
        <mass>0.00000001</mass>
        <inertia>
          <ixx>0.000001</ixx>
          <ixy>0.0</ixy>
          <iyy>0.000001</iyy>
          <ixz>0.0</ixz>
          <iyz>0.0</iyz>
          <izz>0.000001</izz>
        </inertia>
        <pose>-0.073 0 -0.174479 0 -0 0</pose>
      </inertial>

      <visual name='visual'>
        <pose>0 0 0 0 -0 3.1415926</pose>
        <geometry>
          <mesh>
            <uri>model://SHC09/meshes/control surface-60-80-1.STL</uri>
            <scale>1 1 1</scale>
          </mesh>
        </geometry>
        <material>
          <lighting>1</lighting>
          <script>
            <uri>file://media/materials/scripts/gazebo.material</uri>
            <name>Gazebo/Grey</name>
          </script>
          <shader type='pixel'/>
          <emissive>0 0 0 1</emissive>
        </material>
        <transparency>0</transparency>
        <cast_shadows>1</cast_shadows>
      </visual>
    </link>
    <link name='link_30'>
      <inertial>
        <mass>0.00000001</mass>
        <inertia>
          <ixx>0.000001</ixx>
          <ixy>0.0</ixy>
          <iyy>0.000001</iyy>
          <ixz>0.0</ixz>
          <iyz>0.0</iyz>
          <izz>0.000001</izz>
        </inertia>
      </inertial>

      <visual name='visual'>
        <pose>0 0 0 0 -0 3.1415926</pose>
        <geometry>
          <mesh>
            <uri>model://SHC09/meshes/tail-SHW09-1.STL</uri>
            <scale>1 1 1</scale>
          </mesh>
        </geometry>
        <material>
          <lighting>1</lighting>
          <script>
            <uri>file://media/materials/scripts/gazebo.material</uri>
            <name>Gazebo/Black</name>
          </script>
          <shader type='pixel'/>
          <emissive>0 0 0 1</emissive>
        </material>
        <transparency>0</transparency>
        <cast_shadows>1</cast_shadows>
      </visual>
    </link>
    <link name='link_31'>
      <inertial>
        <mass>0.00000001</mass>
        <inertia>
          <ixx>0.000001</ixx>
          <ixy>0.0</ixy>
          <iyy>0.000001</iyy>
          <ixz>0.0</ixz>
          <iyz>0.0</iyz>
          <izz>0.000001</izz>
        </inertia>
      </inertial>

      <visual name='visual'>
        <pose>0 0 0 0 -0 3.1415926</pose>
        <geometry>
          <mesh>
            <uri>model://SHC09/meshes/tail-SHW09-2.STL</uri>
            <scale>1 1 1</scale>
          </mesh>
        </geometry>
        <material>
          <lighting>1</lighting>
          <script>
            <uri>file://media/materials/scripts/gazebo.material</uri>
            <name>Gazebo/Black</name>
          </script>
          <shader type='pixel'/>
          <emissive>0 0 0 1</emissive>
        </material>
        <transparency>0</transparency>
        <cast_shadows>1</cast_shadows>
      </visual>
    </link>
    <link name='link_32'>
      <inertial>
        <mass>0.00000001</mass>
        <inertia>
          <ixx>0.000001</ixx>
          <ixy>0.0</ixy>
          <iyy>0.000001</iyy>
          <ixz>0.0</ixz>
          <iyz>0.0</iyz>
          <izz>0.000001</izz>
        </inertia>
      </inertial>

      <visual name='visual'>
        <pose>0 0 0 0 -0 3.1415926</pose>
        <geometry>
          <mesh>
            <uri>model://SHC09/meshes/tail-SHW09-3.STL</uri>
            <scale>1 1 1</scale>
          </mesh>
        </geometry>
        <material>
          <lighting>1</lighting>
          <script>
            <uri>file://media/materials/scripts/gazebo.material</uri>
            <name>Gazebo/Black</name>
          </script>
          <shader type='pixel'/>
          <emissive>0 0 0 1</emissive>
        </material>
        <transparency>0</transparency>
        <cast_shadows>1</cast_shadows>
      </visual>
    </link>
    <link name='link_33'>
      <inertial>
        <mass>0.00000001</mass>
        <inertia>
          <ixx>0.000001</ixx>
          <ixy>0.0</ixy>
          <iyy>0.000001</iyy>
          <ixz>0.0</ixz>
          <iyz>0.0</iyz>
          <izz>0.000001</izz>
        </inertia>
      </inertial>

      <visual name='visual'>
        <pose>0 0 0 0 -0 3.1415926</pose>
        <geometry>
          <mesh>
            <uri>model://SHC09/meshes/X-tend.STL</uri>
            <scale>1 1 1</scale>
          </mesh>
        </geometry>
        <material>
          <lighting>1</lighting>
          <script>
            <uri>file://media/materials/scripts/gazebo.material</uri>
            <name>Gazebo/Black</name>
          </script>
          <shader type='pixel'/>
          <emissive>0 0 0 1</emissive>
        </material>
        <transparency>0</transparency>
        <cast_shadows>1</cast_shadows>
      </visual>
    </link>
    <link name='CS5'>
      <inertial>
        <!-- <mass>0.006</mass>
        <inertia>
          <ixx>0.000003</ixx>
          <ixy>0</ixy>
          <ixz>0</ixz>
          <iyy>0.000002</iyy>
          <iyz>0</iyz>
          <izz>0.000003</izz>
        </inertia> -->
        <mass>0.00000001</mass>
        <inertia>
          <ixx>0.000001</ixx>
          <ixy>0.0</ixy>
          <iyy>0.000001</iyy>
          <ixz>0.0</ixz>
          <iyz>0.0</iyz>
          <izz>0.000001</izz>
        </inertia>
        <pose>-0.036849 0.063825 -0.174479 0 -0 0</pose>
      </inertial>

      <visual name='visual'>
        <pose>0 0 0 0 -0 3.1415926</pose>
        <geometry>
          <mesh>
            <uri>model://SHC09/meshes/control surface-60-80-2.STL</uri>
            <scale>1 1 1</scale>
          </mesh>
        </geometry>
        <material>
          <lighting>1</lighting>
          <script>
            <uri>file://media/materials/scripts/gazebo.material</uri>
            <name>Gazebo/Grey</name>
          </script>
          <shader type='pixel'/>
          <emissive>0 0 0 1</emissive>
        </material>
        <transparency>0</transparency>
        <cast_shadows>1</cast_shadows>
      </visual>
    </link>
    <link name='CS6'>
      <inertial>
        <!-- <mass>0.006</mass>
        <inertia>
          <ixx>0.000003</ixx>
          <ixy>0</ixy>
          <ixz>0</ixz>
          <iyy>0.000002</iyy>
          <iyz>0</iyz>
          <izz>0.000003</izz>
        </inertia> -->
        <mass>0.00000001</mass>
        <inertia>
          <ixx>0.000001</ixx>
          <ixy>0.0</ixy>
          <iyy>0.000001</iyy>
          <ixz>0.0</ixz>
          <iyz>0.0</iyz>
          <izz>0.000001</izz>
        </inertia>
        <pose>0.036849 0.063825 -0.174479 0 -0 0</pose>
      </inertial>

      <visual name='visual'>
        <pose>0 0 0 0 -0 3.1415926</pose>
        <geometry>
          <mesh>
            <uri>model://SHC09/meshes/control surface-60-80-3.STL</uri>
            <scale>1 1 1</scale>
          </mesh>
        </geometry>
        <material>
          <lighting>1</lighting>
          <script>
            <uri>file://media/materials/scripts/gazebo.material</uri>
            <name>Gazebo/Grey</name>
          </script>
          <shader type='pixel'/>
          <emissive>0 0 0 1</emissive>
        </material>
        <transparency>0</transparency>
        <cast_shadows>1</cast_shadows>
      </visual>
    </link>
    <link name='CS1'>
      <inertial>
        <!-- <mass>0.006</mass>
        <inertia>
          <ixx>0.000001</ixx>
          <ixy>0</ixy>
          <ixz>0</ixz>
          <iyy>0.000004</iyy>
          <iyz>0</iyz>
          <izz>0.000003</izz>
        </inertia> -->
        <mass>0.00000001</mass>
        <inertia>
          <ixx>0.000001</ixx>
          <ixy>0.0</ixy>
          <iyy>0.000001</iyy>
          <ixz>0.0</ixz>
          <iyz>0.0</iyz>
          <izz>0.000001</izz>
        </inertia>
        <pose>0.073699 0 -0.174479 0 -0 0</pose>
      </inertial>

      <visual name='visual'>
        <pose>0 0 0 0 -0 3.1415926</pose>
        <geometry>
          <mesh>
            <uri>model://SHC09/meshes/control surface-60-80-4.STL</uri>
            <scale>1 1 1</scale>
          </mesh>
        </geometry>
        <material>
          <lighting>1</lighting>
          <script>
            <uri>file://media/materials/scripts/gazebo.material</uri>
            <name>Gazebo/Grey</name>
          </script>
          <shader type='pixel'/>
          <emissive>0 0 0 1</emissive>
        </material>
        <transparency>0</transparency>
        <cast_shadows>1</cast_shadows>
      </visual>
    </link>
    <link name='CS2'>
      <inertial>
        <!-- <mass>0.006</mass>
        <inertia>
          <ixx>0.000003</ixx>
          <ixy>0</ixy>
          <ixz>0</ixz>
          <iyy>0.000002</iyy>
          <iyz>0</iyz>
          <izz>0.000003</izz>
        </inertia> -->
        <mass>0.00000001</mass>
        <inertia>
          <ixx>0.000001</ixx>
          <ixy>0.0</ixy>
          <iyy>0.000001</iyy>
          <ixz>0.0</ixz>
          <iyz>0.0</iyz>
          <izz>0.000001</izz>
        </inertia>
        <pose>0.036849 -0.063825 -0.174479 0 -0 0</pose>
      </inertial>

      <visual name='visual'>
        <pose>0 0 0 0 -0 3.1415926</pose>
        <geometry>
          <mesh>
            <uri>model://SHC09/meshes/control surface-60-80-5.STL</uri>
            <scale>1 1 1</scale>
          </mesh>
        </geometry>
        <material>
          <lighting>1</lighting>
          <script>
            <uri>file://media/materials/scripts/gazebo.material</uri>
            <name>Gazebo/Grey</name>
          </script>
          <shader type='pixel'/>
          <emissive>0 0 0 1</emissive>
        </material>
        <transparency>0</transparency>
        <cast_shadows>1</cast_shadows>
      </visual>
    </link>
    <link name='CS3'>
      <inertial>
        <!-- <mass>0.006</mass>
        <inertia>
          <ixx>0.000003</ixx>
          <ixy>0</ixy>
          <ixz>0</ixz>
          <iyy>0.000002</iyy>
          <iyz>0</iyz>
          <izz>0.000003</izz>
        </inertia> -->
        <mass>0.00000001</mass>
        <inertia>
          <ixx>0.000001</ixx>
          <ixy>0.0</ixy>
          <iyy>0.000001</iyy>
          <ixz>0.0</ixz>
          <iyz>0.0</iyz>
          <izz>0.000001</izz>
        </inertia>
        <pose>-0.036849 -0.063825 -0.174479 0 -0 0</pose>
      </inertial>

      <visual name='visual'>
        <pose>0 0 0 0 -0 3.1415926</pose>
        <geometry>
          <mesh>
            <uri>model://SHC09/meshes/control surface-60-80-6.STL</uri>
            <scale>1 1 1</scale>
          </mesh>
        </geometry>
        <material>
          <lighting>1</lighting>
          <script>
            <uri>file://media/materials/scripts/gazebo.material</uri>
            <name>Gazebo/Grey</name>
          </script>
          <shader type='pixel'/>
          <emissive>0 0 0 1</emissive>
        </material>
        <transparency>0</transparency>
        <cast_shadows>1</cast_shadows>
      </visual>
    </link>
    <link name='link_9'>
      <inertial>
        <mass>0.00000001</mass>
        <inertia>
          <ixx>0.000001</ixx>
          <ixy>0.0</ixy>
          <iyy>0.000001</iyy>
          <ixz>0.0</ixz>
          <iyz>0.0</iyz>
          <izz>0.000001</izz>
        </inertia>
      </inertial>

      <visual name='visual'>
        <pose>0 0 0 0 -0 3.1415926</pose>
        <geometry>
          <mesh>
            <uri>model://SHC09/meshes/controller3STL.STL</uri>
            <scale>1 1 1</scale>
          </mesh>
        </geometry>
        <material>
          <lighting>1</lighting>
          <script>
            <uri>file://media/materials/scripts/gazebo.material</uri>
            <name>Gazebo/Green</name>
          </script>
          <shader type='pixel'/>
          <emissive>0 0 0 1</emissive>
        </material>
        <transparency>0</transparency>
        <cast_shadows>1</cast_shadows>
      </visual>
    </link>
    <joint name='link_0_JOINT_0' type='fixed'>
      <parent>base_link</parent>
      <child>link_1</child>
      <pose>0 0 0 0 -0 0</pose>
    </joint>
    <joint name='link_0_JOINT_10' type='fixed'>
      <parent>base_link</parent>
      <child>link_10</child>
      <pose>0 0 0 0 -0 0</pose>
    </joint>
    <joint name='link_0_JOINT_11' type='fixed'>
      <parent>base_link</parent>
      <child>link_11</child>
      <pose>0 0 0 0 -0 0</pose>
    </joint>
    <joint name='link_0_JOINT_12' type='fixed'>
      <parent>base_link</parent>
      <child>link_12</child>
      <pose>0 0 0 0 -0 0</pose>
    </joint>
    <joint name='link_0_JOINT_13' type='fixed'>
      <parent>base_link</parent>
      <child>link_13</child>
      <pose>0 0 0 0 -0 0</pose>
    </joint>
    <joint name='link_0_JOINT_14' type='fixed'>
      <parent>base_link</parent>
      <child>link_14</child>
      <pose>0 0 0 0 -0 0</pose>
    </joint>
    <joint name='link_0_JOINT_15' type='fixed'>
      <parent>base_link</parent>
      <child>link_15</child>
      <pose>0 0 0 0 -0 0</pose>
    </joint>
    <joint name='link_0_JOINT_16' type='fixed'>
      <parent>base_link</parent>
      <child>link_16</child>
      <pose>0 0 0 0 -0 0</pose>
    </joint>
    <joint name='link_0_JOINT_17' type='fixed'>
      <parent>base_link</parent>
      <child>link_17</child>
      <pose>0 0 0 0 -0 0</pose>
    </joint>
    <joint name='rotor_joint' type='revolute'>
      <parent>base_link</parent>
      <child>rotor</child>
      <pose>0 0 -0.04 0 -0 0</pose>
      <axis>
        <xyz>0 0 1</xyz>
        <use_parent_model_frame>0</use_parent_model_frame>
        <limit>
          <lower>-1e+16</lower>
          <upper>1e+16</upper>
          <effort>-1</effort>
          <velocity>-1</velocity>
        </limit>
        <dynamics>
          <spring_reference>0</spring_reference>
          <spring_stiffness>0</spring_stiffness>
          <damping>0.0001</damping>
          <friction>0</friction>
        </dynamics>
      </axis>
      <physics>
        <ode>
          <implicit_spring_damper>1</implicit_spring_damper>
        </ode>
      </physics>
    </joint>
    <joint name='link_0_JOINT_19' type='fixed'>
      <parent>base_link</parent>
      <child>link_19</child>
      <pose>0 0 0 0 -0 0</pose>
    </joint>
    <joint name='link_0_JOINT_1' type='fixed'>
      <parent>base_link</parent>
      <child>link_2</child>
      <pose>0 0 0 0 -0 0</pose>
    </joint>
    <joint name='link_0_JOINT_20' type='fixed'>
      <parent>base_link</parent>
      <child>link_20</child>
      <pose>0 0 0 0 -0 0</pose>
    </joint>
    <joint name='link_0_JOINT_21' type='fixed'>
      <parent>base_link</parent>
      <child>link_21</child>
      <pose>0 0 0 0 -0 0</pose>
    </joint>
    <joint name='link_0_JOINT_22' type='fixed'>
      <parent>base_link</parent>
      <child>link_22</child>
      <pose>0 0 0 0 -0 0</pose>
    </joint>
    <joint name='link_0_JOINT_23' type='fixed'>
      <parent>base_link</parent>
      <child>link_23</child>
      <pose>0 0 0 0 -0 0</pose>
    </joint>
    <joint name='link_0_JOINT_24' type='fixed'>
      <parent>base_link</parent>
      <child>link_24</child>
      <pose>0 0 0 0 -0 0</pose>
    </joint>
    <joint name='link_0_JOINT_25' type='fixed'>
      <parent>base_link</parent>
      <child>link_25</child>
      <pose>0 0 0 0 -0 0</pose>
    </joint>
    <joint name='link_0_JOINT_26' type='fixed'>
      <parent>base_link</parent>
      <child>link_26</child>
      <pose>0 0 0 0 -0 0</pose>
    </joint>
    <joint name='link_0_JOINT_27' type='fixed'>
      <parent>base_link</parent>
      <child>link_27</child>
      <pose>0 0 0 0 -0 0</pose>
    </joint>
    <joint name='link_0_JOINT_28' type='fixed'>
      <parent>base_link</parent>
      <child>link_28</child>
      <pose>0 0 0 0 -0 0</pose>
    </joint>
    <joint name='link_0_JOINT_29' type='fixed'>
      <parent>base_link</parent>
      <child>link_29</child>
      <pose>0 0 0 0 -0 0</pose>
    </joint>
    <joint name='link_0_JOINT_30' type='fixed'>
      <parent>base_link</parent>
      <child>link_30</child>
      <pose>0 0 0 0 -0 0</pose>
    </joint>
    <joint name='link_0_JOINT_31' type='fixed'>
      <parent>base_link</parent>
      <child>link_31</child>
      <pose>0 0 0 0 -0 0</pose>
    </joint>
    <joint name='link_0_JOINT_32' type='fixed'>
      <parent>base_link</parent>
      <child>link_32</child>
      <pose>0 0 0 0 -0 0</pose>
    </joint>
    <joint name='link_0_JOINT_33' type='fixed'>
      <parent>base_link</parent>
      <child>link_33</child>
      <pose>0 0 0 0 -0 0</pose>
    </joint>
    <joint name='link_0_JOINT_8' type='fixed'>
      <parent>base_link</parent>
      <child>link_9</child>
      <pose>0 0 0 0 -0 0</pose>
    </joint>

    <joint name='CS1_joint' type='revolute'>
      <parent>base_link</parent>
      <child>CS1</child>
      <pose>0 0 -0.158 0 0 0</pose>
      <axis>
        <xyz>1 0 0</xyz>
        <limit>
          <lower>-0.5</lower>
          <upper>0.5</upper>
        </limit>
        <dynamics>
          <damping>0.001</damping>
        </dynamics>
      </axis>
      <physics>
        <ode>
          <implicit_spring_damper>1</implicit_spring_damper>
        </ode>
      </physics>

    </joint>
    <joint name='CS2_joint' type='revolute'>
      <parent>base_link</parent>
      <child>CS2</child>
      <pose>0 0 -0.158 0 -0 -1.0472</pose>
      <axis>
        <xyz>1 0 0</xyz>
        <limit>
          <lower>-0.5</lower>
          <upper>0.5</upper>
        </limit>
        <dynamics>
          <damping>0.001</damping>
        </dynamics>
      </axis>
      <physics>
        <ode>
          <implicit_spring_damper>1</implicit_spring_damper>
        </ode>
      </physics>

    </joint>
    <joint name='CS3_joint' type='revolute'>
      <parent>base_link</parent>
      <child>CS3</child>
      <pose>0 0 -0.158 0 -0 -2.0944</pose>
      <axis>
        <xyz>1 0 0</xyz>
        <limit>
          <lower>-0.5</lower>
          <upper>0.5</upper>
        </limit>
        <dynamics>
          <damping>0.001</damping>
        </dynamics>
      </axis>
      <physics>
        <ode>
          <implicit_spring_damper>1</implicit_spring_damper>
        </ode>
      </physics>

    </joint>
    <joint name='CS4_joint' type='revolute'>
      <parent>base_link</parent>
      <child>CS4</child>
      <pose>0 0 -0.158 0 -0 -3.1415</pose>
      <axis>
        <xyz>1 0 0</xyz>
        <limit>
          <lower>-0.5</lower>
          <upper>0.5</upper>
        </limit>
        <dynamics>
          <damping>0.001</damping>
        </dynamics>
      </axis>
      <physics>
        <ode>
          <implicit_spring_damper>1</implicit_spring_damper>
        </ode>
      </physics>

    </joint>
    <joint name='CS5_joint' type='revolute'>
      <parent>base_link</parent>
      <child>CS5</child>
      <pose>0 0 -0.158 0 0 2.0944</pose>
      <axis>
        <xyz>1 0 0</xyz>
        <limit>
          <lower>-0.5</lower>
          <upper>0.5</upper>
        </limit>
        <dynamics>
          <damping>0.001</damping>
        </dynamics>
      </axis>
      <physics>
        <ode>
          <implicit_spring_damper>1</implicit_spring_damper>
        </ode>
      </physics>

    </joint>
    <joint name='CS6_joint' type='revolute'>
      <parent>base_link</parent>
      <child>CS6</child>
      <pose>0 0 -0.158 0 0 1.0472</pose>
      <axis>
        <xyz>1 0 0</xyz>
        <limit>
          <lower>-0.5</lower>
          <upper>0.5</upper>
        </limit>
        <dynamics>
          <damping>0.001</damping>
        </dynamics>
      </axis>
      <physics>
        <ode>
          <implicit_spring_damper>1</implicit_spring_damper>
        </ode>
      </physics>

    </joint>
    <link name='SHC09/imu_link'>
      <pose>0 0 0 0 0 0</pose>
      <inertial>
        <pose>0 0 0 0 0 0</pose>
        <mass>0.015</mass>
        <inertia>
          <ixx>1e-05</ixx>
          <ixy>0</ixy>
          <ixz>0</ixz>
          <iyy>1e-05</iyy>
          <iyz>0</iyz>
          <izz>1e-05</izz>
        </inertia>
      </inertial>
    </link>
    <joint name='SHC09/imu_joint' type='revolute'>
      <child>SHC09/imu_link</child>
      <parent>base_link</parent>
      <axis>
        <xyz>1 0 0</xyz>
        <limit>
          <lower>0</lower>
          <upper>0</upper>
          <effort>0</effort>
          <velocity>0</velocity>
        </limit>
        <dynamics>
          <spring_reference>0</spring_reference>
          <spring_stiffness>0</spring_stiffness>
        </dynamics>
        <use_parent_model_frame>1</use_parent_model_frame>
      </axis>
    </joint>
    <link name='SHC09/airspeed_link'>
      <pose>0 0 0 0 0 0</pose>
      <inertial>
        <pose>0 0 0 0 0 0</pose>
        <mass>0.015</mass>
        <inertia>
          <ixx>1e-05</ixx>
          <ixy>0</ixy>
          <ixz>0</ixz>
          <iyy>1e-05</iyy>
          <iyz>0</iyz>
          <izz>1e-05</izz>
        </inertia>
      </inertial>
    </link>
    <joint name='SHC09/airspeed_joint' type='revolute'>
      <child>SHC09/airspeed_link</child>
      <parent>base_link</parent>
      <axis>
        <xyz>1 0 0</xyz>
        <limit>
          <lower>0</lower>
          <upper>0</upper>
          <effort>0</effort>
          <velocity>0</velocity>
        </limit>
        <dynamics>
          <spring_reference>0</spring_reference>
          <spring_stiffness>0</spring_stiffness>
        </dynamics>
        <use_parent_model_frame>1</use_parent_model_frame>
      </axis>
    </joint>
    <include>
      <uri>model://gps</uri>
      <pose>0 0 0 0 0 0</pose>
      <name>gps</name>
    </include>
    <joint name='gps_joint' type='fixed'>
      <child>gps::link</child>
      <parent>base_link</parent>
    </joint>
    <plugin name="CS1_plugin" filename="libLiftDragPlugin.so">
      <propeller_wind_map>
        <propeller joint="rotor_joint" k_v="0.01" rotorVelocitySlowdownSim="10" />
        <wash_only>false</wash_only>
      </propeller_wind_map>
      <a0>0</a0>
      <cla>0</cla>
      <cda>0</cda>
      <cma>0</cma>
      <alpha_stall>0.6</alpha_stall>
      <cla_stall>0</cla_stall>
      <cda_stall>0.0</cda_stall>
      <cma_stall>0</cma_stall>
      <cp>0.073699 0 -0.174479</cp>
      <area>0.0018</area>
      <air_density>1.2041</air_density>
      <forward>0 0 1</forward>
      <upward>0 -1 0</upward>
      <link_name>base_link</link_name>
      <control_joint_name>CS1_joint</control_joint_name>
      <control_joint_rad_to_cl>6.7362</control_joint_rad_to_cl>
      <robotNamespace></robotNamespace>
      <windSubTopic>world_wind</windSubTopic>
    </plugin>
    <plugin name="CS6_plugin" filename="libLiftDragPlugin.so">
      <propeller_wind_map>
        <propeller joint="rotor_joint" k_v="0.01" rotorVelocitySlowdownSim="10" />
        <wash_only>false</wash_only>
      </propeller_wind_map>
      <a0>0</a0>
      <cla>0</cla>
      <cda>0</cda>
      <cma>0</cma>
      <alpha_stall>0.6</alpha_stall>
      <cla_stall>0</cla_stall>
      <cda_stall>0.0</cda_stall>
      <cma_stall>0</cma_stall>
      <cp>0.036849 0.063825 -0.174479</cp>
      <area>0.0018</area>
      <air_density>1.2041</air_density>
      <forward>0 0 1</forward>
      <upward>0.866 -0.5 0</upward>
      <link_name>base_link</link_name>
      <control_joint_name>CS6_joint</control_joint_name>
      <control_joint_rad_to_cl>6.7362</control_joint_rad_to_cl>
      <robotNamespace></robotNamespace>
      <windSubTopic>world_wind</windSubTopic>
    </plugin>
    <plugin name="CS3_plugin" filename="libLiftDragPlugin.so">
      <propeller_wind_map>
        <propeller joint="rotor_joint" k_v="0.01" rotorVelocitySlowdownSim="10" />
        <wash_only>false</wash_only>
      </propeller_wind_map>
      <a0>0</a0>
      <cla>0</cla>
      <cda>0</cda>
      <cma>0</cma>
      <alpha_stall>0.6</alpha_stall>
      <cla_stall>0</cla_stall>
      <cda_stall>0.0</cda_stall>
      <cma_stall>0</cma_stall>
      <cp>-0.036849 -0.063825 -0.174479</cp>
      <area>0.0018</area>
      <air_density>1.2041</air_density>
      <forward>0 0 1</forward>
      <upward>-0.866 0.5 0</upward>
      <link_name>base_link</link_name>
      <control_joint_name>CS3_joint</control_joint_name>
      <control_joint_rad_to_cl>6.7362</control_joint_rad_to_cl>
      <robotNamespace></robotNamespace>
      <windSubTopic>world_wind</windSubTopic>
    </plugin>
    <plugin name="CS2_plugin" filename="libLiftDragPlugin.so">
      <propeller_wind_map>
        <propeller joint="rotor_joint" k_v="0.01" rotorVelocitySlowdownSim="10" />
        <wash_only>false</wash_only>
      </propeller_wind_map>
      <a0>0</a0>
      <cla>0</cla>
      <cda>0</cda>
      <cma>0</cma>
      <alpha_stall>0.6</alpha_stall>
      <cla_stall>0</cla_stall>
      <cda_stall>0.0</cda_stall>
      <cma_stall>0</cma_stall>
      <cp>0.036849 -0.063825 -0.174479</cp>
      <area>0.0018</area>
      <air_density>1.2041</air_density>
      <forward>0 0 1</forward>
      <upward>-0.866 -0.5 0</upward>
      <link_name>base_link</link_name>
      <control_joint_name>CS2_joint</control_joint_name>
      <control_joint_rad_to_cl>6.7362</control_joint_rad_to_cl>
      <robotNamespace></robotNamespace>
      <windSubTopic>world_wind</windSubTopic>
    </plugin>

    <plugin name="CS4_plugin" filename="libLiftDragPlugin.so">
      <propeller_wind_map>
        <propeller joint="rotor_joint" k_v="0.01" rotorVelocitySlowdownSim="10" />
        <wash_only>false</wash_only>
      </propeller_wind_map>
      <a0>0</a0>
      <cla>0</cla>
      <cda>0</cda>
      <cma>0</cma>
      <alpha_stall>0.6</alpha_stall>
      <cla_stall>0</cla_stall>
      <cda_stall>0.0</cda_stall>
      <cma_stall>0</cma_stall>
      <cp>-0.073699 0 -0.174479</cp>
      <area>0.0018</area>
      <air_density>1.2041</air_density>
      <forward>0 0 1</forward>
      <upward>0 1 0</upward>
      <link_name>base_link</link_name>
      <control_joint_name>CS4_joint</control_joint_name>
      <control_joint_rad_to_cl>6.7362</control_joint_rad_to_cl>
      <robotNamespace></robotNamespace>
      <windSubTopic>world_wind</windSubTopic>
    </plugin>
    <plugin name="CS5_plugin" filename="libLiftDragPlugin.so">
      <propeller_wind_map>
        <propeller joint="rotor_joint" k_v="0.01" rotorVelocitySlowdownSim="10" />
        <wash_only>false</wash_only>
      </propeller_wind_map>
      <a0>0</a0>
      <cla>0</cla>
      <cda>0</cda>
      <cma>0</cma>
      <alpha_stall>0.6</alpha_stall>
      <cla_stall>0</cla_stall>
      <cda_stall>0.0</cda_stall>
      <cma_stall>0</cma_stall>
      <cp>-0.036849 0.063825 -0.174479</cp>
      <area>0.0018</area>
      <air_density>1.2041</air_density>
      <forward>0 0 1</forward>
      <upward>0.866 0.5 0</upward>
      <link_name>base_link</link_name>
      <control_joint_name>CS5_joint</control_joint_name>
      <control_joint_rad_to_cl>6.7362</control_joint_rad_to_cl>
      <robotNamespace></robotNamespace>
      <windSubTopic>world_wind</windSubTopic>
    </plugin>

    <plugin name='rotor_ductedfan_plugin' filename='libDuctedFanPlugin.so'>
      <robotNamespace></robotNamespace>
      <jointName>rotor_joint</jointName>
      <linkName>rotor</linkName>
      <turningDirection>ccw</turningDirection>
      <timeConstantUp>0.0125</timeConstantUp>
      <timeConstantDown>0.025</timeConstantDown>
      <maxRotVelocity>2450</maxRotVelocity>
      <!-- Lift Force T -->
      <motorConstant>1.405e-05</motorConstant>
      <!-- The Drag moment generated by the rotation of the rotor (the same as T) -->
      <momentConstant>2.35e-05</momentConstant>
      <commandSubTopic>/gazebo/command/motor_speed</commandSubTopic>
      <motorNumber>0</motorNumber>
      <!-- Air Drag Force H acting on rotor due to relative wind vel-->
      <rotorDragCoefficient>0</rotorDragCoefficient>
      <!-- Rolling moment due to air drag Force H -->
      <rollingMomentCoefficient>0</rollingMomentCoefficient>
      <motorSpeedPubTopic>/motor_speed/0</motorSpeedPubTopic>
      <rotorVelocitySlowdownSim>10</rotorVelocitySlowdownSim>
      <robotNamespace></robotNamespace>
    </plugin>

    <plugin name='gazebo_imu_plugin' filename='libgazebo_imu_plugin.so'>
      <robotNamespace></robotNamespace>
      <linkName>SHC09/imu_link</linkName>
      <imuTopic>/imu</imuTopic>
      <gyroscopeNoiseDensity>0.00018665</gyroscopeNoiseDensity>
      <gyroscopeRandomWalk>3.8785e-05</gyroscopeRandomWalk>
      <gyroscopeBiasCorrelationTime>1000.0</gyroscopeBiasCorrelationTime>
      <gyroscopeTurnOnBiasSigma>0.0087</gyroscopeTurnOnBiasSigma>
      <accelerometerNoiseDensity>0.00186</accelerometerNoiseDensity>
      <accelerometerRandomWalk>0.006</accelerometerRandomWalk>
      <accelerometerBiasCorrelationTime>300.0</accelerometerBiasCorrelationTime>
      <accelerometerTurnOnBiasSigma>0.196</accelerometerTurnOnBiasSigma>
    </plugin>
    <plugin name='groundtruth_plugin' filename='libgazebo_groundtruth_plugin.so'>
      <robotNamespace/>
    </plugin>
    <plugin name='magnetometer_plugin' filename='libgazebo_magnetometer_plugin.so'>
      <robotNamespace/>
      <pubRate>100</pubRate>
      <noiseDensity>0.0004</noiseDensity>
      <randomWalk>6.4e-06</randomWalk>
      <biasCorrelationTime>600</biasCorrelationTime>
      <magTopic>/mag</magTopic>
    </plugin>
    <plugin name='barometer_plugin' filename='libgazebo_barometer_plugin.so'>
      <robotNamespace/>
      <pubRate>50</pubRate>
      <baroTopic>/baro</baroTopic>
    </plugin>
    <plugin name='airspeed_plugin' filename='libgazebo_airspeed_plugin.so'>
      <robotNamespace/>
      <linkName>SHC09/airspeed_link</linkName>
    </plugin>
    <plugin name='mavlink_interface' filename='libgazebo_mavlink_interface.so'>
      <robotNamespace></robotNamespace>
      <imuSubTopic>/imu</imuSubTopic>
      <magSubTopic>/mag</magSubTopic>
      <baroSubTopic>/baro</baroSubTopic>
      <mavlink_addr>INADDR_ANY</mavlink_addr>
      <mavlink_tcp_port>4560</mavlink_tcp_port>
      <mavlink_udp_port>14560</mavlink_udp_port>
      <serialEnabled>0</serialEnabled>
      <serialDevice>/dev/ttyACM0</serialDevice>
      <baudRate>921600</baudRate>
      <qgc_addr>INADDR_ANY</qgc_addr>
      <qgc_udp_port>14550</qgc_udp_port>
      <sdk_addr>INADDR_ANY</sdk_addr>
      <sdk_udp_port>14540</sdk_udp_port>
      <hil_mode>0</hil_mode>
      <hil_state_level>false</hil_state_level>
      <enable_lockstep>true</enable_lockstep>
      <use_tcp>true</use_tcp>
      <motorSpeedCommandPubTopic>/gazebo/command/motor_speed</motorSpeedCommandPubTopic>
      <control_channels>
        <channel name="up_rotor">
          <input_index>0</input_index>
          <input_offset>0</input_offset>
          <!-- Construct a gain to cancel the link from pwm to motor speed. -->
          <input_scaling>2450</input_scaling>
          <zero_position_disarmed>0</zero_position_disarmed>
          <zero_position_armed>0</zero_position_armed>
          <joint_control_type>velocity</joint_control_type>
          <joint_name>rotor_joint</joint_name>
        </channel>
        <channel name="1">
          <input_index>4</input_index>
          <input_offset>0</input_offset>
          <input_scaling>0.35</input_scaling>
          <zero_position_disarmed>0</zero_position_disarmed>
          <zero_position_armed>0</zero_position_armed>
          <joint_control_type>position_kinematic</joint_control_type>
          <joint_name>CS1_joint</joint_name>
        </channel>
        <channel name="2">
          <input_index>5</input_index>
          <input_offset>0</input_offset>
          <input_scaling>0.35</input_scaling>
          <zero_position_disarmed>0</zero_position_disarmed>
          <zero_position_armed>0</zero_position_armed>
          <joint_control_type>position_kinematic</joint_control_type>
          <joint_name>CS2_joint</joint_name>
        </channel>
        <channel name="3">
          <input_index>6</input_index>
          <input_offset>0</input_offset>
          <input_scaling>0.35</input_scaling>
          <zero_position_disarmed>0</zero_position_disarmed>
          <zero_position_armed>0</zero_position_armed>
          <joint_control_type>position_kinematic</joint_control_type>
          <joint_name>CS3_joint</joint_name>
        </channel>
        <channel name="4">
          <input_index>7</input_index>
          <input_offset>0</input_offset>
          <input_scaling>0.35</input_scaling>
          <zero_position_disarmed>0</zero_position_disarmed>
          <zero_position_armed>0</zero_position_armed>
          <joint_control_type>position_kinematic</joint_control_type>
          <joint_name>CS4_joint</joint_name>
        </channel>
        <channel name="5">
          <input_index>8</input_index>
          <input_offset>0</input_offset>
          <input_scaling>0.35</input_scaling>
          <zero_position_disarmed>0</zero_position_disarmed>
          <zero_position_armed>0</zero_position_armed>
          <joint_control_type>position_kinematic</joint_control_type>
          <joint_name>CS5_joint</joint_name>
        </channel>
        <channel name="6">
          <input_index>9</input_index>
          <input_offset>0</input_offset>
          <input_scaling>0.35</input_scaling>
          <zero_position_disarmed>0</zero_position_disarmed>
          <zero_position_armed>0</zero_position_armed>
          <joint_control_type>position_kinematic</joint_control_type>
          <joint_name>CS6_joint</joint_name>
        </channel>

      </control_channels>
    </plugin>
    <static>0</static>
  </model>
</sdf>